{
 "cells": [
  {
   "cell_type": "code",
   "execution_count": 1,
   "id": "19cea087-c522-4b8c-91cb-809003136bda",
   "metadata": {},
   "outputs": [],
   "source": [
    "import os\n",
    "import cv2\n",
    "from subprocess import call\n",
    "from ultralytics import YOLO\n",
    "import tensorflow.compat.v1 as tf"
   ]
  },
  {
   "cell_type": "code",
   "execution_count": 24,
   "id": "1f2f1010-ec33-456d-98ec-905860b491dd",
   "metadata": {},
   "outputs": [],
   "source": [
    "import tensorflow.compat.v1 as tf\n",
    "tf.disable_eager_execution()\n",
    "\n",
    "# Example of a simple TensorFlow 1.x model\n",
    "x = tf.placeholder(tf.float32, shape=[None, 10], name='x')\n",
    "y = tf.placeholder(tf.float32, shape=[None, 1], name='y')\n",
    "weights = tf.Variable(tf.random_normal([10, 1]), name='weights')\n",
    "bias = tf.Variable(tf.zeros([1]), name='bias')\n",
    "\n",
    "predictions = tf.add(tf.matmul(x, weights), bias, name='predictions')\n",
    "loss = tf.reduce_mean(tf.square(predictions - y), name='loss')\n",
    "train_op = tf.train.AdamOptimizer(0.001).minimize(loss)\n"
   ]
  },
  {
   "cell_type": "code",
   "execution_count": 25,
   "id": "9ba81842-96e6-45dc-9d5b-f271b9c03750",
   "metadata": {},
   "outputs": [],
   "source": [
    "# Save model\n",
    "saver = tf.train.Saver()\n",
    "with tf.Session() as sess:\n",
    "    sess.run(tf.global_variables_initializer())\n",
    "    saver.save(sess, 'saved_model/my_model.ckpt')\n"
   ]
  },
  {
   "cell_type": "code",
   "execution_count": 26,
   "id": "3ba53887-4a33-4db8-b8e4-40842dbd5f59",
   "metadata": {},
   "outputs": [
    {
     "name": "stdout",
     "output_type": "stream",
     "text": [
      "INFO:tensorflow:Restoring parameters from saved_model/my_model.ckpt\n",
      "Model restored successfully.\n"
     ]
    }
   ],
   "source": [
    "saver = tf.train.Saver()\n",
    "with tf.Session() as sess:\n",
    "    saver.restore(sess, 'saved_model/my_model.ckpt')\n",
    "    print(\"Model restored successfully.\")\n"
   ]
  },
  {
   "cell_type": "code",
   "execution_count": null,
   "id": "ef9ddb71-52e4-4d0d-9182-d8ed46009f92",
   "metadata": {},
   "outputs": [],
   "source": []
  },
  {
   "cell_type": "code",
   "execution_count": null,
   "id": "b3831550-8077-4934-9dcb-f8e2c46d67cd",
   "metadata": {},
   "outputs": [],
   "source": []
  },
  {
   "cell_type": "code",
   "execution_count": null,
   "id": "29678ff7-1393-4f15-baa1-f41401140ff5",
   "metadata": {},
   "outputs": [],
   "source": []
  },
  {
   "cell_type": "code",
   "execution_count": 27,
   "id": "3fd529d6-c030-4ccc-94e8-c2d15f0a996b",
   "metadata": {},
   "outputs": [],
   "source": [
    "class SteeringAnglePredictor:\n",
    "    def __init__(self, model_path):\n",
    "        \"\"\"\n",
    "        Initialize the predictor by restoring a TensorFlow 1.x model.\n",
    "\n",
    "        Args:\n",
    "            model_path (str): Path to the saved TensorFlow 1.x model checkpoint.\n",
    "        \"\"\"\n",
    "        self.session = tf.Session()  # Create a session for TensorFlow 1.x\n",
    "\n",
    "        # Restore the graph and variables\n",
    "        saver = tf.train.import_meta_graph(model_path + '.meta')\n",
    "        saver.restore(self.session, model_path)\n",
    "\n",
    "        # Access tensors from the restored graph\n",
    "        self.graph = tf.get_default_graph()\n",
    "        self.x = self.graph.get_tensor_by_name('x:0')\n",
    "        self.keep_prob = self.graph.get_tensor_by_name('keep_prob:0')  # Replace as needed\n",
    "        self.y = self.graph.get_tensor_by_name('y:0')\n",
    "\n",
    "        self.smoothed_angle = 0\n",
    "\n",
    "    def predict_angle(self, image):\n",
    "        \"\"\"\n",
    "        Predict the steering angle from a preprocessed image.\n",
    "\n",
    "        Args:\n",
    "            image (numpy.ndarray): Preprocessed input image.\n",
    "\n",
    "        Returns:\n",
    "            float: Predicted steering angle in degrees.\n",
    "        \"\"\"\n",
    "        predicted_radians = self.session.run(self.y, feed_dict={self.x: [image], self.keep_prob: 1.0})[0][0]\n",
    "        return predicted_radians * 180.0 / 3.14159265  # Convert radians to degrees\n",
    "\n",
    "    def smooth_angle(self, predicted_angle):\n",
    "        \"\"\"\n",
    "        Smooth the predicted steering angle for consistent control.\n",
    "\n",
    "        Args:\n",
    "            predicted_angle (float): Raw predicted angle in degrees.\n",
    "\n",
    "        Returns:\n",
    "            float: Smoothed steering angle.\n",
    "        \"\"\"\n",
    "        if self.smoothed_angle == 0:\n",
    "            self.smoothed_angle = predicted_angle\n",
    "        else:\n",
    "            self.smoothed_angle += 0.2 * pow(abs(predicted_angle - self.smoothed_angle), 2.0 / 3.0) * (\n",
    "                (predicted_angle - self.smoothed_angle) / abs(predicted_angle - self.smoothed_angle)\n",
    "            )\n",
    "        return self.smoothed_angle\n",
    "\n",
    "    def close(self):\n",
    "        \"\"\"Close the TensorFlow session.\"\"\"\n",
    "        self.session.close()\n"
   ]
  },
  {
   "cell_type": "code",
   "execution_count": 18,
   "id": "945d4445-1e70-4a60-9138-78ee02fd3db6",
   "metadata": {},
   "outputs": [],
   "source": [
    "class DrivingSimulator:\n",
    "    def __init__(self, predictor, data_dir, steering_image_path, is_windows=False):\n",
    "        self.predictor = predictor\n",
    "        self.data_dir = data_dir\n",
    "        self.steering_image = cv2.imread(steering_image_path, 0)\n",
    "        self.is_windows = is_windows\n",
    "        self.rows, self.cols = self.steering_image.shape\n",
    "\n",
    "    def start_simulation(self):\n",
    "        i = 0\n",
    "        while cv2.waitKey(10) != ord('q'):\n",
    "            full_image = cv2.imread(os.path.join(self.data_dir, f\"{i}.jpg\"))\n",
    "            resized_image = cv2.resize(full_image[-150:], (200, 66)) / 255.0\n",
    "\n",
    "            predicted_angle = self.predictor.predict_angle(resized_image)\n",
    "            smoothed_angle = self.predictor.smooth_angle(predicted_angle)\n",
    "\n",
    "            if not self.is_windows:\n",
    "                call(\"clear\")\n",
    "            print(f\"Predicted steering angle: {predicted_angle} degrees\")\n",
    "\n",
    "            self.display_frames(full_image, smoothed_angle)\n",
    "            i += 1\n",
    "\n",
    "        cv2.destroyAllWindows()\n",
    "        \n",
    "        def display_frames(self, full_image, smoothed_angle):\n",
    "            cv2.imshow(\"frame\", full_image)\n",
    "            rotation_matrix = cv2.getRotationMatrix2D((self.cols / 2, self.rows / 2), -smoothed_angle, 1)\n",
    "            rotated_steering_wheel = cv2.warpAffine(self.steering_image, rotation_matrix, (self.cols, self.rows))\n",
    "            cv2.imshow(\"steering wheel\", rotated_steering_wheel)"
   ]
  },
  {
   "cell_type": "code",
   "execution_count": 30,
   "id": "1ea847f1-d3d3-4110-ac5d-30c312cf6e3b",
   "metadata": {
    "scrolled": true
   },
   "outputs": [
    {
     "ename": "OSError",
     "evalue": "File does not exist. Received: saved_model/regression_model/model_22.keras.meta.",
     "output_type": "error",
     "traceback": [
      "\u001b[1;31m---------------------------------------------------------------------------\u001b[0m",
      "\u001b[1;31mOSError\u001b[0m                                   Traceback (most recent call last)",
      "Cell \u001b[1;32mIn[30], line 10\u001b[0m\n\u001b[0;32m      7\u001b[0m \u001b[38;5;66;03m# Determine if running on Windows\u001b[39;00m\n\u001b[0;32m      8\u001b[0m is_windows \u001b[38;5;241m=\u001b[39m os\u001b[38;5;241m.\u001b[39mname \u001b[38;5;241m==\u001b[39m \u001b[38;5;124m'\u001b[39m\u001b[38;5;124mnt\u001b[39m\u001b[38;5;124m'\u001b[39m\n\u001b[1;32m---> 10\u001b[0m predictor \u001b[38;5;241m=\u001b[39m \u001b[43mSteeringAnglePredictor\u001b[49m\u001b[43m(\u001b[49m\u001b[43mmodel_path\u001b[49m\u001b[43m)\u001b[49m\n\u001b[0;32m     11\u001b[0m simulator \u001b[38;5;241m=\u001b[39m DrivingSimulator(predictor, data_dir, steering_image_path, is_windows)\n\u001b[0;32m     13\u001b[0m \u001b[38;5;28;01mtry\u001b[39;00m:\n",
      "Cell \u001b[1;32mIn[27], line 12\u001b[0m, in \u001b[0;36mSteeringAnglePredictor.__init__\u001b[1;34m(self, model_path)\u001b[0m\n\u001b[0;32m      9\u001b[0m \u001b[38;5;28mself\u001b[39m\u001b[38;5;241m.\u001b[39msession \u001b[38;5;241m=\u001b[39m tf\u001b[38;5;241m.\u001b[39mSession()  \u001b[38;5;66;03m# Create a session for TensorFlow 1.x\u001b[39;00m\n\u001b[0;32m     11\u001b[0m \u001b[38;5;66;03m# Restore the graph and variables\u001b[39;00m\n\u001b[1;32m---> 12\u001b[0m saver \u001b[38;5;241m=\u001b[39m \u001b[43mtf\u001b[49m\u001b[38;5;241;43m.\u001b[39;49m\u001b[43mtrain\u001b[49m\u001b[38;5;241;43m.\u001b[39;49m\u001b[43mimport_meta_graph\u001b[49m\u001b[43m(\u001b[49m\u001b[43mmodel_path\u001b[49m\u001b[43m \u001b[49m\u001b[38;5;241;43m+\u001b[39;49m\u001b[43m \u001b[49m\u001b[38;5;124;43m'\u001b[39;49m\u001b[38;5;124;43m.meta\u001b[39;49m\u001b[38;5;124;43m'\u001b[39;49m\u001b[43m)\u001b[49m\n\u001b[0;32m     13\u001b[0m saver\u001b[38;5;241m.\u001b[39mrestore(\u001b[38;5;28mself\u001b[39m\u001b[38;5;241m.\u001b[39msession, model_path)\n\u001b[0;32m     15\u001b[0m \u001b[38;5;66;03m# Access tensors from the restored graph\u001b[39;00m\n",
      "File \u001b[1;32m~\\AppData\\Local\\Programs\\Python\\Python311\\Lib\\site-packages\\tensorflow\\python\\training\\saver.py:1587\u001b[0m, in \u001b[0;36mimport_meta_graph\u001b[1;34m(meta_graph_or_file, clear_devices, import_scope, **kwargs)\u001b[0m\n\u001b[0;32m   1477\u001b[0m \u001b[38;5;129m@tf_export\u001b[39m(v1\u001b[38;5;241m=\u001b[39m[\u001b[38;5;124m\"\u001b[39m\u001b[38;5;124mtrain.import_meta_graph\u001b[39m\u001b[38;5;124m\"\u001b[39m])\n\u001b[0;32m   1478\u001b[0m \u001b[38;5;28;01mdef\u001b[39;00m \u001b[38;5;21mimport_meta_graph\u001b[39m(meta_graph_or_file,\n\u001b[0;32m   1479\u001b[0m                       clear_devices\u001b[38;5;241m=\u001b[39m\u001b[38;5;28;01mFalse\u001b[39;00m,\n\u001b[0;32m   1480\u001b[0m                       import_scope\u001b[38;5;241m=\u001b[39m\u001b[38;5;28;01mNone\u001b[39;00m,\n\u001b[0;32m   1481\u001b[0m                       \u001b[38;5;241m*\u001b[39m\u001b[38;5;241m*\u001b[39mkwargs):\n\u001b[0;32m   1482\u001b[0m \u001b[38;5;250m  \u001b[39m\u001b[38;5;124;03m\"\"\"Recreates a Graph saved in a `MetaGraphDef` proto.\u001b[39;00m\n\u001b[0;32m   1483\u001b[0m \n\u001b[0;32m   1484\u001b[0m \u001b[38;5;124;03m  This function takes a `MetaGraphDef` protocol buffer as input. If\u001b[39;00m\n\u001b[1;32m   (...)\u001b[0m\n\u001b[0;32m   1585\u001b[0m \u001b[38;5;124;03m  @end_compatibility\u001b[39;00m\n\u001b[0;32m   1586\u001b[0m \u001b[38;5;124;03m  \"\"\"\u001b[39;00m  \u001b[38;5;66;03m# pylint: disable=g-doc-exception\u001b[39;00m\n\u001b[1;32m-> 1587\u001b[0m   \u001b[38;5;28;01mreturn\u001b[39;00m \u001b[43m_import_meta_graph_with_return_elements\u001b[49m\u001b[43m(\u001b[49m\u001b[43mmeta_graph_or_file\u001b[49m\u001b[43m,\u001b[49m\n\u001b[0;32m   1588\u001b[0m \u001b[43m                                                 \u001b[49m\u001b[43mclear_devices\u001b[49m\u001b[43m,\u001b[49m\u001b[43m \u001b[49m\u001b[43mimport_scope\u001b[49m\u001b[43m,\u001b[49m\n\u001b[0;32m   1589\u001b[0m \u001b[43m                                                 \u001b[49m\u001b[38;5;241;43m*\u001b[39;49m\u001b[38;5;241;43m*\u001b[39;49m\u001b[43mkwargs\u001b[49m\u001b[43m)\u001b[49m[\u001b[38;5;241m0\u001b[39m]\n",
      "File \u001b[1;32m~\\AppData\\Local\\Programs\\Python\\Python311\\Lib\\site-packages\\tensorflow\\python\\training\\saver.py:1603\u001b[0m, in \u001b[0;36m_import_meta_graph_with_return_elements\u001b[1;34m(meta_graph_or_file, clear_devices, import_scope, return_elements, **kwargs)\u001b[0m\n\u001b[0;32m   1599\u001b[0m   \u001b[38;5;28;01mraise\u001b[39;00m \u001b[38;5;167;01mRuntimeError\u001b[39;00m(\u001b[38;5;124m\"\u001b[39m\u001b[38;5;124mExporting/importing meta graphs is not supported when \u001b[39m\u001b[38;5;124m\"\u001b[39m\n\u001b[0;32m   1600\u001b[0m                      \u001b[38;5;124m\"\u001b[39m\u001b[38;5;124meager execution is enabled. No graph exists when eager \u001b[39m\u001b[38;5;124m\"\u001b[39m\n\u001b[0;32m   1601\u001b[0m                      \u001b[38;5;124m\"\u001b[39m\u001b[38;5;124mexecution is enabled.\u001b[39m\u001b[38;5;124m\"\u001b[39m)\n\u001b[0;32m   1602\u001b[0m \u001b[38;5;28;01mif\u001b[39;00m \u001b[38;5;129;01mnot\u001b[39;00m \u001b[38;5;28misinstance\u001b[39m(meta_graph_or_file, meta_graph_pb2\u001b[38;5;241m.\u001b[39mMetaGraphDef):\n\u001b[1;32m-> 1603\u001b[0m   meta_graph_def \u001b[38;5;241m=\u001b[39m \u001b[43mmeta_graph\u001b[49m\u001b[38;5;241;43m.\u001b[39;49m\u001b[43mread_meta_graph_file\u001b[49m\u001b[43m(\u001b[49m\u001b[43mmeta_graph_or_file\u001b[49m\u001b[43m)\u001b[49m\n\u001b[0;32m   1604\u001b[0m \u001b[38;5;28;01melse\u001b[39;00m:\n\u001b[0;32m   1605\u001b[0m   meta_graph_def \u001b[38;5;241m=\u001b[39m meta_graph_or_file\n",
      "File \u001b[1;32m~\\AppData\\Local\\Programs\\Python\\Python311\\Lib\\site-packages\\tensorflow\\python\\framework\\meta_graph.py:611\u001b[0m, in \u001b[0;36mread_meta_graph_file\u001b[1;34m(filename)\u001b[0m\n\u001b[0;32m    609\u001b[0m meta_graph_def \u001b[38;5;241m=\u001b[39m meta_graph_pb2\u001b[38;5;241m.\u001b[39mMetaGraphDef()\n\u001b[0;32m    610\u001b[0m \u001b[38;5;28;01mif\u001b[39;00m \u001b[38;5;129;01mnot\u001b[39;00m file_io\u001b[38;5;241m.\u001b[39mfile_exists(filename):\n\u001b[1;32m--> 611\u001b[0m   \u001b[38;5;28;01mraise\u001b[39;00m \u001b[38;5;167;01mIOError\u001b[39;00m(\u001b[38;5;124mf\u001b[39m\u001b[38;5;124m\"\u001b[39m\u001b[38;5;124mFile does not exist. Received: \u001b[39m\u001b[38;5;132;01m{\u001b[39;00mfilename\u001b[38;5;132;01m}\u001b[39;00m\u001b[38;5;124m.\u001b[39m\u001b[38;5;124m\"\u001b[39m)\n\u001b[0;32m    612\u001b[0m \u001b[38;5;66;03m# First try to read it as a binary file.\u001b[39;00m\n\u001b[0;32m    613\u001b[0m \u001b[38;5;28;01mwith\u001b[39;00m file_io\u001b[38;5;241m.\u001b[39mFileIO(filename, \u001b[38;5;124m\"\u001b[39m\u001b[38;5;124mrb\u001b[39m\u001b[38;5;124m\"\u001b[39m) \u001b[38;5;28;01mas\u001b[39;00m f:\n",
      "\u001b[1;31mOSError\u001b[0m: File does not exist. Received: saved_model/regression_model/model_22.keras.meta."
     ]
    }
   ],
   "source": [
    "if __name__ == \"__main__\":\n",
    "    tf.disable_v2_behavior()\n",
    "    model_path = 'saved_model/regression_model/model_22.keras'\n",
    "    data_dir = \"data/driving_dataset\"\n",
    "    steering_image_path = \"data/steering_wheel_image.jpg\"\n",
    "\n",
    "    # Determine if running on Windows\n",
    "    is_windows = os.name == 'nt'\n",
    "\n",
    "    predictor = SteeringAnglePredictor(model_path)\n",
    "    simulator = DrivingSimulator(predictor, data_dir, steering_image_path, is_windows)\n",
    "\n",
    "    try:\n",
    "        simulator.start_simulation()\n",
    "    finally:\n",
    "        predictor.close()"
   ]
  },
  {
   "cell_type": "code",
   "execution_count": 31,
   "id": "41f0da1d-38be-4a3f-890f-edbbeaeefe24",
   "metadata": {},
   "outputs": [
    {
     "name": "stdout",
     "output_type": "stream",
     "text": [
      "INFO:tensorflow:Restoring parameters from saved_model/regression_model/model_22.keras\n"
     ]
    },
    {
     "ename": "DataLossError",
     "evalue": "Graph execution error:\n\nDetected at node 'save_2/RestoreV2' defined at (most recent call last):\n    File \"<frozen runpy>\", line 198, in _run_module_as_main\n    File \"<frozen runpy>\", line 88, in _run_code\n    File \"C:\\Users\\OM CHAVAN\\AppData\\Local\\Programs\\Python\\Python311\\Lib\\site-packages\\ipykernel_launcher.py\", line 17, in <module>\n    File \"C:\\Users\\OM CHAVAN\\AppData\\Local\\Programs\\Python\\Python311\\Lib\\site-packages\\traitlets\\config\\application.py\", line 1043, in launch_instance\n    File \"C:\\Users\\OM CHAVAN\\AppData\\Local\\Programs\\Python\\Python311\\Lib\\site-packages\\ipykernel\\kernelapp.py\", line 736, in start\n    File \"C:\\Users\\OM CHAVAN\\AppData\\Local\\Programs\\Python\\Python311\\Lib\\site-packages\\tornado\\platform\\asyncio.py\", line 195, in start\n    File \"C:\\Users\\OM CHAVAN\\AppData\\Local\\Programs\\Python\\Python311\\Lib\\asyncio\\base_events.py\", line 607, in run_forever\n    File \"C:\\Users\\OM CHAVAN\\AppData\\Local\\Programs\\Python\\Python311\\Lib\\asyncio\\base_events.py\", line 1922, in _run_once\n    File \"C:\\Users\\OM CHAVAN\\AppData\\Local\\Programs\\Python\\Python311\\Lib\\asyncio\\events.py\", line 80, in _run\n    File \"C:\\Users\\OM CHAVAN\\AppData\\Local\\Programs\\Python\\Python311\\Lib\\site-packages\\ipykernel\\kernelbase.py\", line 516, in dispatch_queue\n    File \"C:\\Users\\OM CHAVAN\\AppData\\Local\\Programs\\Python\\Python311\\Lib\\site-packages\\ipykernel\\kernelbase.py\", line 505, in process_one\n    File \"C:\\Users\\OM CHAVAN\\AppData\\Local\\Programs\\Python\\Python311\\Lib\\site-packages\\ipykernel\\kernelbase.py\", line 412, in dispatch_shell\n    File \"C:\\Users\\OM CHAVAN\\AppData\\Local\\Programs\\Python\\Python311\\Lib\\site-packages\\ipykernel\\kernelbase.py\", line 740, in execute_request\n    File \"C:\\Users\\OM CHAVAN\\AppData\\Local\\Programs\\Python\\Python311\\Lib\\site-packages\\ipykernel\\ipkernel.py\", line 422, in do_execute\n    File \"C:\\Users\\OM CHAVAN\\AppData\\Local\\Programs\\Python\\Python311\\Lib\\site-packages\\ipykernel\\zmqshell.py\", line 546, in run_cell\n    File \"C:\\Users\\OM CHAVAN\\AppData\\Local\\Programs\\Python\\Python311\\Lib\\site-packages\\IPython\\core\\interactiveshell.py\", line 3009, in run_cell\n    File \"C:\\Users\\OM CHAVAN\\AppData\\Local\\Programs\\Python\\Python311\\Lib\\site-packages\\IPython\\core\\interactiveshell.py\", line 3064, in _run_cell\n    File \"C:\\Users\\OM CHAVAN\\AppData\\Local\\Programs\\Python\\Python311\\Lib\\site-packages\\IPython\\core\\async_helpers.py\", line 129, in _pseudo_sync_runner\n    File \"C:\\Users\\OM CHAVAN\\AppData\\Local\\Programs\\Python\\Python311\\Lib\\site-packages\\IPython\\core\\interactiveshell.py\", line 3269, in run_cell_async\n    File \"C:\\Users\\OM CHAVAN\\AppData\\Local\\Programs\\Python\\Python311\\Lib\\site-packages\\IPython\\core\\interactiveshell.py\", line 3448, in run_ast_nodes\n    File \"C:\\Users\\OM CHAVAN\\AppData\\Local\\Programs\\Python\\Python311\\Lib\\site-packages\\IPython\\core\\interactiveshell.py\", line 3508, in run_code\n    File \"C:\\Users\\OM CHAVAN\\AppData\\Local\\Temp\\ipykernel_62912\\2824488194.py\", line 12, in <module>\nNode: 'save_2/RestoreV2'\nUnable to open table file saved_model\\regression_model\\model_22.keras: DATA_LOSS: not an sstable (bad magic number): perhaps your file is in a different file format and you need to use a different restore operator?\n\t [[{{node save_2/RestoreV2}}]]\n\nOriginal stack trace for 'save_2/RestoreV2':\n  File \"<frozen runpy>\", line 198, in _run_module_as_main\n  File \"<frozen runpy>\", line 88, in _run_code\n  File \"C:\\Users\\OM CHAVAN\\AppData\\Local\\Programs\\Python\\Python311\\Lib\\site-packages\\ipykernel_launcher.py\", line 17, in <module>\n  File \"C:\\Users\\OM CHAVAN\\AppData\\Local\\Programs\\Python\\Python311\\Lib\\site-packages\\traitlets\\config\\application.py\", line 1043, in launch_instance\n  File \"C:\\Users\\OM CHAVAN\\AppData\\Local\\Programs\\Python\\Python311\\Lib\\site-packages\\ipykernel\\kernelapp.py\", line 736, in start\n  File \"C:\\Users\\OM CHAVAN\\AppData\\Local\\Programs\\Python\\Python311\\Lib\\site-packages\\tornado\\platform\\asyncio.py\", line 195, in start\n  File \"C:\\Users\\OM CHAVAN\\AppData\\Local\\Programs\\Python\\Python311\\Lib\\asyncio\\base_events.py\", line 607, in run_forever\n  File \"C:\\Users\\OM CHAVAN\\AppData\\Local\\Programs\\Python\\Python311\\Lib\\asyncio\\base_events.py\", line 1922, in _run_once\n  File \"C:\\Users\\OM CHAVAN\\AppData\\Local\\Programs\\Python\\Python311\\Lib\\asyncio\\events.py\", line 80, in _run\n  File \"C:\\Users\\OM CHAVAN\\AppData\\Local\\Programs\\Python\\Python311\\Lib\\site-packages\\ipykernel\\kernelbase.py\", line 516, in dispatch_queue\n  File \"C:\\Users\\OM CHAVAN\\AppData\\Local\\Programs\\Python\\Python311\\Lib\\site-packages\\ipykernel\\kernelbase.py\", line 505, in process_one\n  File \"C:\\Users\\OM CHAVAN\\AppData\\Local\\Programs\\Python\\Python311\\Lib\\site-packages\\ipykernel\\kernelbase.py\", line 412, in dispatch_shell\n  File \"C:\\Users\\OM CHAVAN\\AppData\\Local\\Programs\\Python\\Python311\\Lib\\site-packages\\ipykernel\\kernelbase.py\", line 740, in execute_request\n  File \"C:\\Users\\OM CHAVAN\\AppData\\Local\\Programs\\Python\\Python311\\Lib\\site-packages\\ipykernel\\ipkernel.py\", line 422, in do_execute\n  File \"C:\\Users\\OM CHAVAN\\AppData\\Local\\Programs\\Python\\Python311\\Lib\\site-packages\\ipykernel\\zmqshell.py\", line 546, in run_cell\n  File \"C:\\Users\\OM CHAVAN\\AppData\\Local\\Programs\\Python\\Python311\\Lib\\site-packages\\IPython\\core\\interactiveshell.py\", line 3009, in run_cell\n  File \"C:\\Users\\OM CHAVAN\\AppData\\Local\\Programs\\Python\\Python311\\Lib\\site-packages\\IPython\\core\\interactiveshell.py\", line 3064, in _run_cell\n  File \"C:\\Users\\OM CHAVAN\\AppData\\Local\\Programs\\Python\\Python311\\Lib\\site-packages\\IPython\\core\\async_helpers.py\", line 129, in _pseudo_sync_runner\n  File \"C:\\Users\\OM CHAVAN\\AppData\\Local\\Programs\\Python\\Python311\\Lib\\site-packages\\IPython\\core\\interactiveshell.py\", line 3269, in run_cell_async\n  File \"C:\\Users\\OM CHAVAN\\AppData\\Local\\Programs\\Python\\Python311\\Lib\\site-packages\\IPython\\core\\interactiveshell.py\", line 3448, in run_ast_nodes\n  File \"C:\\Users\\OM CHAVAN\\AppData\\Local\\Programs\\Python\\Python311\\Lib\\site-packages\\IPython\\core\\interactiveshell.py\", line 3508, in run_code\n  File \"C:\\Users\\OM CHAVAN\\AppData\\Local\\Temp\\ipykernel_62912\\2824488194.py\", line 12, in <module>\n  File \"C:\\Users\\OM CHAVAN\\AppData\\Local\\Programs\\Python\\Python311\\Lib\\site-packages\\tensorflow\\python\\training\\saver.py\", line 934, in __init__\n  File \"C:\\Users\\OM CHAVAN\\AppData\\Local\\Programs\\Python\\Python311\\Lib\\site-packages\\tensorflow\\python\\training\\saver.py\", line 946, in build\n  File \"C:\\Users\\OM CHAVAN\\AppData\\Local\\Programs\\Python\\Python311\\Lib\\site-packages\\tensorflow\\python\\training\\saver.py\", line 974, in _build\n  File \"C:\\Users\\OM CHAVAN\\AppData\\Local\\Programs\\Python\\Python311\\Lib\\site-packages\\tensorflow\\python\\training\\saver.py\", line 543, in _build_internal\n  File \"C:\\Users\\OM CHAVAN\\AppData\\Local\\Programs\\Python\\Python311\\Lib\\site-packages\\tensorflow\\python\\training\\saver.py\", line 360, in _AddRestoreOps\n  File \"C:\\Users\\OM CHAVAN\\AppData\\Local\\Programs\\Python\\Python311\\Lib\\site-packages\\tensorflow\\python\\training\\saver.py\", line 611, in bulk_restore\n  File \"C:\\Users\\OM CHAVAN\\AppData\\Local\\Programs\\Python\\Python311\\Lib\\site-packages\\tensorflow\\python\\ops\\gen_io_ops.py\", line 1610, in restore_v2\n  File \"C:\\Users\\OM CHAVAN\\AppData\\Local\\Programs\\Python\\Python311\\Lib\\site-packages\\tensorflow\\python\\framework\\op_def_library.py\", line 796, in _apply_op_helper\n  File \"C:\\Users\\OM CHAVAN\\AppData\\Local\\Programs\\Python\\Python311\\Lib\\site-packages\\tensorflow\\python\\framework\\ops.py\", line 2701, in _create_op_internal\n  File \"C:\\Users\\OM CHAVAN\\AppData\\Local\\Programs\\Python\\Python311\\Lib\\site-packages\\tensorflow\\python\\framework\\ops.py\", line 1196, in from_node_def\n",
     "output_type": "error",
     "traceback": [
      "\u001b[1;31m---------------------------------------------------------------------------\u001b[0m",
      "\u001b[1;31mDataLossError\u001b[0m                             Traceback (most recent call last)",
      "File \u001b[1;32m~\\AppData\\Local\\Programs\\Python\\Python311\\Lib\\site-packages\\tensorflow\\python\\client\\session.py:1407\u001b[0m, in \u001b[0;36mBaseSession._do_call\u001b[1;34m(self, fn, *args)\u001b[0m\n\u001b[0;32m   1406\u001b[0m \u001b[38;5;28;01mtry\u001b[39;00m:\n\u001b[1;32m-> 1407\u001b[0m   \u001b[38;5;28;01mreturn\u001b[39;00m \u001b[43mfn\u001b[49m\u001b[43m(\u001b[49m\u001b[38;5;241;43m*\u001b[39;49m\u001b[43margs\u001b[49m\u001b[43m)\u001b[49m\n\u001b[0;32m   1408\u001b[0m \u001b[38;5;28;01mexcept\u001b[39;00m errors\u001b[38;5;241m.\u001b[39mOpError \u001b[38;5;28;01mas\u001b[39;00m e:\n",
      "File \u001b[1;32m~\\AppData\\Local\\Programs\\Python\\Python311\\Lib\\site-packages\\tensorflow\\python\\client\\session.py:1390\u001b[0m, in \u001b[0;36mBaseSession._do_run.<locals>._run_fn\u001b[1;34m(feed_dict, fetch_list, target_list, options, run_metadata)\u001b[0m\n\u001b[0;32m   1389\u001b[0m \u001b[38;5;28mself\u001b[39m\u001b[38;5;241m.\u001b[39m_extend_graph()\n\u001b[1;32m-> 1390\u001b[0m \u001b[38;5;28;01mreturn\u001b[39;00m \u001b[38;5;28;43mself\u001b[39;49m\u001b[38;5;241;43m.\u001b[39;49m\u001b[43m_call_tf_sessionrun\u001b[49m\u001b[43m(\u001b[49m\u001b[43moptions\u001b[49m\u001b[43m,\u001b[49m\u001b[43m \u001b[49m\u001b[43mfeed_dict\u001b[49m\u001b[43m,\u001b[49m\u001b[43m \u001b[49m\u001b[43mfetch_list\u001b[49m\u001b[43m,\u001b[49m\n\u001b[0;32m   1391\u001b[0m \u001b[43m                                \u001b[49m\u001b[43mtarget_list\u001b[49m\u001b[43m,\u001b[49m\u001b[43m \u001b[49m\u001b[43mrun_metadata\u001b[49m\u001b[43m)\u001b[49m\n",
      "File \u001b[1;32m~\\AppData\\Local\\Programs\\Python\\Python311\\Lib\\site-packages\\tensorflow\\python\\client\\session.py:1483\u001b[0m, in \u001b[0;36mBaseSession._call_tf_sessionrun\u001b[1;34m(self, options, feed_dict, fetch_list, target_list, run_metadata)\u001b[0m\n\u001b[0;32m   1481\u001b[0m \u001b[38;5;28;01mdef\u001b[39;00m \u001b[38;5;21m_call_tf_sessionrun\u001b[39m(\u001b[38;5;28mself\u001b[39m, options, feed_dict, fetch_list, target_list,\n\u001b[0;32m   1482\u001b[0m                         run_metadata):\n\u001b[1;32m-> 1483\u001b[0m   \u001b[38;5;28;01mreturn\u001b[39;00m \u001b[43mtf_session\u001b[49m\u001b[38;5;241;43m.\u001b[39;49m\u001b[43mTF_SessionRun_wrapper\u001b[49m\u001b[43m(\u001b[49m\u001b[38;5;28;43mself\u001b[39;49m\u001b[38;5;241;43m.\u001b[39;49m\u001b[43m_session\u001b[49m\u001b[43m,\u001b[49m\u001b[43m \u001b[49m\u001b[43moptions\u001b[49m\u001b[43m,\u001b[49m\u001b[43m \u001b[49m\u001b[43mfeed_dict\u001b[49m\u001b[43m,\u001b[49m\n\u001b[0;32m   1484\u001b[0m \u001b[43m                                          \u001b[49m\u001b[43mfetch_list\u001b[49m\u001b[43m,\u001b[49m\u001b[43m \u001b[49m\u001b[43mtarget_list\u001b[49m\u001b[43m,\u001b[49m\n\u001b[0;32m   1485\u001b[0m \u001b[43m                                          \u001b[49m\u001b[43mrun_metadata\u001b[49m\u001b[43m)\u001b[49m\n",
      "\u001b[1;31mDataLossError\u001b[0m: Unable to open table file saved_model\\regression_model\\model_22.keras: DATA_LOSS: not an sstable (bad magic number): perhaps your file is in a different file format and you need to use a different restore operator?\n\t [[{{node save_2/RestoreV2}}]]",
      "\nDuring handling of the above exception, another exception occurred:\n",
      "\u001b[1;31mDataLossError\u001b[0m                             Traceback (most recent call last)",
      "Cell \u001b[1;32mIn[31], line 14\u001b[0m\n\u001b[0;32m     12\u001b[0m saver \u001b[38;5;241m=\u001b[39m tf\u001b[38;5;241m.\u001b[39mtrain\u001b[38;5;241m.\u001b[39mSaver()\n\u001b[0;32m     13\u001b[0m \u001b[38;5;28;01mwith\u001b[39;00m tf\u001b[38;5;241m.\u001b[39mSession() \u001b[38;5;28;01mas\u001b[39;00m sess:\n\u001b[1;32m---> 14\u001b[0m     \u001b[43msaver\u001b[49m\u001b[38;5;241;43m.\u001b[39;49m\u001b[43mrestore\u001b[49m\u001b[43m(\u001b[49m\u001b[43msess\u001b[49m\u001b[43m,\u001b[49m\u001b[43m \u001b[49m\u001b[38;5;124;43m'\u001b[39;49m\u001b[38;5;124;43msaved_model/regression_model/model_22.keras\u001b[39;49m\u001b[38;5;124;43m'\u001b[39;49m\u001b[43m)\u001b[49m\n\u001b[0;32m     15\u001b[0m     \u001b[38;5;28mprint\u001b[39m(\u001b[38;5;124m\"\u001b[39m\u001b[38;5;124mModel restored successfully!\u001b[39m\u001b[38;5;124m\"\u001b[39m)\n",
      "File \u001b[1;32m~\\AppData\\Local\\Programs\\Python\\Python311\\Lib\\site-packages\\tensorflow\\python\\training\\saver.py:1422\u001b[0m, in \u001b[0;36mSaver.restore\u001b[1;34m(self, sess, save_path)\u001b[0m\n\u001b[0;32m   1420\u001b[0m     \u001b[38;5;28mself\u001b[39m\u001b[38;5;241m.\u001b[39m_build_eager(save_path, build_save\u001b[38;5;241m=\u001b[39m\u001b[38;5;28;01mFalse\u001b[39;00m, build_restore\u001b[38;5;241m=\u001b[39m\u001b[38;5;28;01mTrue\u001b[39;00m)\n\u001b[0;32m   1421\u001b[0m   \u001b[38;5;28;01melse\u001b[39;00m:\n\u001b[1;32m-> 1422\u001b[0m     \u001b[43msess\u001b[49m\u001b[38;5;241;43m.\u001b[39;49m\u001b[43mrun\u001b[49m\u001b[43m(\u001b[49m\u001b[38;5;28;43mself\u001b[39;49m\u001b[38;5;241;43m.\u001b[39;49m\u001b[43msaver_def\u001b[49m\u001b[38;5;241;43m.\u001b[39;49m\u001b[43mrestore_op_name\u001b[49m\u001b[43m,\u001b[49m\n\u001b[0;32m   1423\u001b[0m \u001b[43m             \u001b[49m\u001b[43m{\u001b[49m\u001b[38;5;28;43mself\u001b[39;49m\u001b[38;5;241;43m.\u001b[39;49m\u001b[43msaver_def\u001b[49m\u001b[38;5;241;43m.\u001b[39;49m\u001b[43mfilename_tensor_name\u001b[49m\u001b[43m:\u001b[49m\u001b[43m \u001b[49m\u001b[43msave_path\u001b[49m\u001b[43m}\u001b[49m\u001b[43m)\u001b[49m\n\u001b[0;32m   1424\u001b[0m \u001b[38;5;28;01mexcept\u001b[39;00m errors\u001b[38;5;241m.\u001b[39mNotFoundError \u001b[38;5;28;01mas\u001b[39;00m err:\n\u001b[0;32m   1425\u001b[0m   \u001b[38;5;66;03m# There are three common conditions that might cause this error:\u001b[39;00m\n\u001b[0;32m   1426\u001b[0m   \u001b[38;5;66;03m# 0. The file is missing. We ignore here, as this is checked above.\u001b[39;00m\n\u001b[1;32m   (...)\u001b[0m\n\u001b[0;32m   1430\u001b[0m   \u001b[38;5;66;03m# 1. The checkpoint would not be loaded successfully as is. Try to parse\u001b[39;00m\n\u001b[0;32m   1431\u001b[0m   \u001b[38;5;66;03m# it as an object-based checkpoint.\u001b[39;00m\n\u001b[0;32m   1432\u001b[0m   \u001b[38;5;28;01mtry\u001b[39;00m:\n",
      "File \u001b[1;32m~\\AppData\\Local\\Programs\\Python\\Python311\\Lib\\site-packages\\tensorflow\\python\\client\\session.py:977\u001b[0m, in \u001b[0;36mBaseSession.run\u001b[1;34m(self, fetches, feed_dict, options, run_metadata)\u001b[0m\n\u001b[0;32m    974\u001b[0m run_metadata_ptr \u001b[38;5;241m=\u001b[39m tf_session\u001b[38;5;241m.\u001b[39mTF_NewBuffer() \u001b[38;5;28;01mif\u001b[39;00m run_metadata \u001b[38;5;28;01melse\u001b[39;00m \u001b[38;5;28;01mNone\u001b[39;00m\n\u001b[0;32m    976\u001b[0m \u001b[38;5;28;01mtry\u001b[39;00m:\n\u001b[1;32m--> 977\u001b[0m   result \u001b[38;5;241m=\u001b[39m \u001b[38;5;28;43mself\u001b[39;49m\u001b[38;5;241;43m.\u001b[39;49m\u001b[43m_run\u001b[49m\u001b[43m(\u001b[49m\u001b[38;5;28;43;01mNone\u001b[39;49;00m\u001b[43m,\u001b[49m\u001b[43m \u001b[49m\u001b[43mfetches\u001b[49m\u001b[43m,\u001b[49m\u001b[43m \u001b[49m\u001b[43mfeed_dict\u001b[49m\u001b[43m,\u001b[49m\u001b[43m \u001b[49m\u001b[43moptions_ptr\u001b[49m\u001b[43m,\u001b[49m\n\u001b[0;32m    978\u001b[0m \u001b[43m                     \u001b[49m\u001b[43mrun_metadata_ptr\u001b[49m\u001b[43m)\u001b[49m\n\u001b[0;32m    979\u001b[0m   \u001b[38;5;28;01mif\u001b[39;00m run_metadata:\n\u001b[0;32m    980\u001b[0m     proto_data \u001b[38;5;241m=\u001b[39m tf_session\u001b[38;5;241m.\u001b[39mTF_GetBuffer(run_metadata_ptr)\n",
      "File \u001b[1;32m~\\AppData\\Local\\Programs\\Python\\Python311\\Lib\\site-packages\\tensorflow\\python\\client\\session.py:1220\u001b[0m, in \u001b[0;36mBaseSession._run\u001b[1;34m(self, handle, fetches, feed_dict, options, run_metadata)\u001b[0m\n\u001b[0;32m   1217\u001b[0m \u001b[38;5;66;03m# We only want to really perform the run if fetches or targets are provided,\u001b[39;00m\n\u001b[0;32m   1218\u001b[0m \u001b[38;5;66;03m# or if the call is a partial run that specifies feeds.\u001b[39;00m\n\u001b[0;32m   1219\u001b[0m \u001b[38;5;28;01mif\u001b[39;00m final_fetches \u001b[38;5;129;01mor\u001b[39;00m final_targets \u001b[38;5;129;01mor\u001b[39;00m (handle \u001b[38;5;129;01mand\u001b[39;00m feed_dict_tensor):\n\u001b[1;32m-> 1220\u001b[0m   results \u001b[38;5;241m=\u001b[39m \u001b[38;5;28;43mself\u001b[39;49m\u001b[38;5;241;43m.\u001b[39;49m\u001b[43m_do_run\u001b[49m\u001b[43m(\u001b[49m\u001b[43mhandle\u001b[49m\u001b[43m,\u001b[49m\u001b[43m \u001b[49m\u001b[43mfinal_targets\u001b[49m\u001b[43m,\u001b[49m\u001b[43m \u001b[49m\u001b[43mfinal_fetches\u001b[49m\u001b[43m,\u001b[49m\n\u001b[0;32m   1221\u001b[0m \u001b[43m                         \u001b[49m\u001b[43mfeed_dict_tensor\u001b[49m\u001b[43m,\u001b[49m\u001b[43m \u001b[49m\u001b[43moptions\u001b[49m\u001b[43m,\u001b[49m\u001b[43m \u001b[49m\u001b[43mrun_metadata\u001b[49m\u001b[43m)\u001b[49m\n\u001b[0;32m   1222\u001b[0m \u001b[38;5;28;01melse\u001b[39;00m:\n\u001b[0;32m   1223\u001b[0m   results \u001b[38;5;241m=\u001b[39m []\n",
      "File \u001b[1;32m~\\AppData\\Local\\Programs\\Python\\Python311\\Lib\\site-packages\\tensorflow\\python\\client\\session.py:1400\u001b[0m, in \u001b[0;36mBaseSession._do_run\u001b[1;34m(self, handle, target_list, fetch_list, feed_dict, options, run_metadata)\u001b[0m\n\u001b[0;32m   1397\u001b[0m   \u001b[38;5;28;01mreturn\u001b[39;00m \u001b[38;5;28mself\u001b[39m\u001b[38;5;241m.\u001b[39m_call_tf_sessionprun(handle, feed_dict, fetch_list)\n\u001b[0;32m   1399\u001b[0m \u001b[38;5;28;01mif\u001b[39;00m handle \u001b[38;5;129;01mis\u001b[39;00m \u001b[38;5;28;01mNone\u001b[39;00m:\n\u001b[1;32m-> 1400\u001b[0m   \u001b[38;5;28;01mreturn\u001b[39;00m \u001b[38;5;28;43mself\u001b[39;49m\u001b[38;5;241;43m.\u001b[39;49m\u001b[43m_do_call\u001b[49m\u001b[43m(\u001b[49m\u001b[43m_run_fn\u001b[49m\u001b[43m,\u001b[49m\u001b[43m \u001b[49m\u001b[43mfeeds\u001b[49m\u001b[43m,\u001b[49m\u001b[43m \u001b[49m\u001b[43mfetches\u001b[49m\u001b[43m,\u001b[49m\u001b[43m \u001b[49m\u001b[43mtargets\u001b[49m\u001b[43m,\u001b[49m\u001b[43m \u001b[49m\u001b[43moptions\u001b[49m\u001b[43m,\u001b[49m\n\u001b[0;32m   1401\u001b[0m \u001b[43m                       \u001b[49m\u001b[43mrun_metadata\u001b[49m\u001b[43m)\u001b[49m\n\u001b[0;32m   1402\u001b[0m \u001b[38;5;28;01melse\u001b[39;00m:\n\u001b[0;32m   1403\u001b[0m   \u001b[38;5;28;01mreturn\u001b[39;00m \u001b[38;5;28mself\u001b[39m\u001b[38;5;241m.\u001b[39m_do_call(_prun_fn, handle, feeds, fetches)\n",
      "File \u001b[1;32m~\\AppData\\Local\\Programs\\Python\\Python311\\Lib\\site-packages\\tensorflow\\python\\client\\session.py:1426\u001b[0m, in \u001b[0;36mBaseSession._do_call\u001b[1;34m(self, fn, *args)\u001b[0m\n\u001b[0;32m   1421\u001b[0m \u001b[38;5;28;01mif\u001b[39;00m \u001b[38;5;124m'\u001b[39m\u001b[38;5;124monly supports NHWC tensor format\u001b[39m\u001b[38;5;124m'\u001b[39m \u001b[38;5;129;01min\u001b[39;00m message:\n\u001b[0;32m   1422\u001b[0m   message \u001b[38;5;241m+\u001b[39m\u001b[38;5;241m=\u001b[39m (\u001b[38;5;124m'\u001b[39m\u001b[38;5;130;01m\\n\u001b[39;00m\u001b[38;5;124mA possible workaround: Try disabling Grappler optimizer\u001b[39m\u001b[38;5;124m'\u001b[39m\n\u001b[0;32m   1423\u001b[0m               \u001b[38;5;124m'\u001b[39m\u001b[38;5;130;01m\\n\u001b[39;00m\u001b[38;5;124mby modifying the config for creating the session eg.\u001b[39m\u001b[38;5;124m'\u001b[39m\n\u001b[0;32m   1424\u001b[0m               \u001b[38;5;124m'\u001b[39m\u001b[38;5;130;01m\\n\u001b[39;00m\u001b[38;5;124msession_config.graph_options.rewrite_options.\u001b[39m\u001b[38;5;124m'\u001b[39m\n\u001b[0;32m   1425\u001b[0m               \u001b[38;5;124m'\u001b[39m\u001b[38;5;124mdisable_meta_optimizer = True\u001b[39m\u001b[38;5;124m'\u001b[39m)\n\u001b[1;32m-> 1426\u001b[0m \u001b[38;5;28;01mraise\u001b[39;00m \u001b[38;5;28mtype\u001b[39m(e)(node_def, op, message)\n",
      "\u001b[1;31mDataLossError\u001b[0m: Graph execution error:\n\nDetected at node 'save_2/RestoreV2' defined at (most recent call last):\n    File \"<frozen runpy>\", line 198, in _run_module_as_main\n    File \"<frozen runpy>\", line 88, in _run_code\n    File \"C:\\Users\\OM CHAVAN\\AppData\\Local\\Programs\\Python\\Python311\\Lib\\site-packages\\ipykernel_launcher.py\", line 17, in <module>\n    File \"C:\\Users\\OM CHAVAN\\AppData\\Local\\Programs\\Python\\Python311\\Lib\\site-packages\\traitlets\\config\\application.py\", line 1043, in launch_instance\n    File \"C:\\Users\\OM CHAVAN\\AppData\\Local\\Programs\\Python\\Python311\\Lib\\site-packages\\ipykernel\\kernelapp.py\", line 736, in start\n    File \"C:\\Users\\OM CHAVAN\\AppData\\Local\\Programs\\Python\\Python311\\Lib\\site-packages\\tornado\\platform\\asyncio.py\", line 195, in start\n    File \"C:\\Users\\OM CHAVAN\\AppData\\Local\\Programs\\Python\\Python311\\Lib\\asyncio\\base_events.py\", line 607, in run_forever\n    File \"C:\\Users\\OM CHAVAN\\AppData\\Local\\Programs\\Python\\Python311\\Lib\\asyncio\\base_events.py\", line 1922, in _run_once\n    File \"C:\\Users\\OM CHAVAN\\AppData\\Local\\Programs\\Python\\Python311\\Lib\\asyncio\\events.py\", line 80, in _run\n    File \"C:\\Users\\OM CHAVAN\\AppData\\Local\\Programs\\Python\\Python311\\Lib\\site-packages\\ipykernel\\kernelbase.py\", line 516, in dispatch_queue\n    File \"C:\\Users\\OM CHAVAN\\AppData\\Local\\Programs\\Python\\Python311\\Lib\\site-packages\\ipykernel\\kernelbase.py\", line 505, in process_one\n    File \"C:\\Users\\OM CHAVAN\\AppData\\Local\\Programs\\Python\\Python311\\Lib\\site-packages\\ipykernel\\kernelbase.py\", line 412, in dispatch_shell\n    File \"C:\\Users\\OM CHAVAN\\AppData\\Local\\Programs\\Python\\Python311\\Lib\\site-packages\\ipykernel\\kernelbase.py\", line 740, in execute_request\n    File \"C:\\Users\\OM CHAVAN\\AppData\\Local\\Programs\\Python\\Python311\\Lib\\site-packages\\ipykernel\\ipkernel.py\", line 422, in do_execute\n    File \"C:\\Users\\OM CHAVAN\\AppData\\Local\\Programs\\Python\\Python311\\Lib\\site-packages\\ipykernel\\zmqshell.py\", line 546, in run_cell\n    File \"C:\\Users\\OM CHAVAN\\AppData\\Local\\Programs\\Python\\Python311\\Lib\\site-packages\\IPython\\core\\interactiveshell.py\", line 3009, in run_cell\n    File \"C:\\Users\\OM CHAVAN\\AppData\\Local\\Programs\\Python\\Python311\\Lib\\site-packages\\IPython\\core\\interactiveshell.py\", line 3064, in _run_cell\n    File \"C:\\Users\\OM CHAVAN\\AppData\\Local\\Programs\\Python\\Python311\\Lib\\site-packages\\IPython\\core\\async_helpers.py\", line 129, in _pseudo_sync_runner\n    File \"C:\\Users\\OM CHAVAN\\AppData\\Local\\Programs\\Python\\Python311\\Lib\\site-packages\\IPython\\core\\interactiveshell.py\", line 3269, in run_cell_async\n    File \"C:\\Users\\OM CHAVAN\\AppData\\Local\\Programs\\Python\\Python311\\Lib\\site-packages\\IPython\\core\\interactiveshell.py\", line 3448, in run_ast_nodes\n    File \"C:\\Users\\OM CHAVAN\\AppData\\Local\\Programs\\Python\\Python311\\Lib\\site-packages\\IPython\\core\\interactiveshell.py\", line 3508, in run_code\n    File \"C:\\Users\\OM CHAVAN\\AppData\\Local\\Temp\\ipykernel_62912\\2824488194.py\", line 12, in <module>\nNode: 'save_2/RestoreV2'\nUnable to open table file saved_model\\regression_model\\model_22.keras: DATA_LOSS: not an sstable (bad magic number): perhaps your file is in a different file format and you need to use a different restore operator?\n\t [[{{node save_2/RestoreV2}}]]\n\nOriginal stack trace for 'save_2/RestoreV2':\n  File \"<frozen runpy>\", line 198, in _run_module_as_main\n  File \"<frozen runpy>\", line 88, in _run_code\n  File \"C:\\Users\\OM CHAVAN\\AppData\\Local\\Programs\\Python\\Python311\\Lib\\site-packages\\ipykernel_launcher.py\", line 17, in <module>\n  File \"C:\\Users\\OM CHAVAN\\AppData\\Local\\Programs\\Python\\Python311\\Lib\\site-packages\\traitlets\\config\\application.py\", line 1043, in launch_instance\n  File \"C:\\Users\\OM CHAVAN\\AppData\\Local\\Programs\\Python\\Python311\\Lib\\site-packages\\ipykernel\\kernelapp.py\", line 736, in start\n  File \"C:\\Users\\OM CHAVAN\\AppData\\Local\\Programs\\Python\\Python311\\Lib\\site-packages\\tornado\\platform\\asyncio.py\", line 195, in start\n  File \"C:\\Users\\OM CHAVAN\\AppData\\Local\\Programs\\Python\\Python311\\Lib\\asyncio\\base_events.py\", line 607, in run_forever\n  File \"C:\\Users\\OM CHAVAN\\AppData\\Local\\Programs\\Python\\Python311\\Lib\\asyncio\\base_events.py\", line 1922, in _run_once\n  File \"C:\\Users\\OM CHAVAN\\AppData\\Local\\Programs\\Python\\Python311\\Lib\\asyncio\\events.py\", line 80, in _run\n  File \"C:\\Users\\OM CHAVAN\\AppData\\Local\\Programs\\Python\\Python311\\Lib\\site-packages\\ipykernel\\kernelbase.py\", line 516, in dispatch_queue\n  File \"C:\\Users\\OM CHAVAN\\AppData\\Local\\Programs\\Python\\Python311\\Lib\\site-packages\\ipykernel\\kernelbase.py\", line 505, in process_one\n  File \"C:\\Users\\OM CHAVAN\\AppData\\Local\\Programs\\Python\\Python311\\Lib\\site-packages\\ipykernel\\kernelbase.py\", line 412, in dispatch_shell\n  File \"C:\\Users\\OM CHAVAN\\AppData\\Local\\Programs\\Python\\Python311\\Lib\\site-packages\\ipykernel\\kernelbase.py\", line 740, in execute_request\n  File \"C:\\Users\\OM CHAVAN\\AppData\\Local\\Programs\\Python\\Python311\\Lib\\site-packages\\ipykernel\\ipkernel.py\", line 422, in do_execute\n  File \"C:\\Users\\OM CHAVAN\\AppData\\Local\\Programs\\Python\\Python311\\Lib\\site-packages\\ipykernel\\zmqshell.py\", line 546, in run_cell\n  File \"C:\\Users\\OM CHAVAN\\AppData\\Local\\Programs\\Python\\Python311\\Lib\\site-packages\\IPython\\core\\interactiveshell.py\", line 3009, in run_cell\n  File \"C:\\Users\\OM CHAVAN\\AppData\\Local\\Programs\\Python\\Python311\\Lib\\site-packages\\IPython\\core\\interactiveshell.py\", line 3064, in _run_cell\n  File \"C:\\Users\\OM CHAVAN\\AppData\\Local\\Programs\\Python\\Python311\\Lib\\site-packages\\IPython\\core\\async_helpers.py\", line 129, in _pseudo_sync_runner\n  File \"C:\\Users\\OM CHAVAN\\AppData\\Local\\Programs\\Python\\Python311\\Lib\\site-packages\\IPython\\core\\interactiveshell.py\", line 3269, in run_cell_async\n  File \"C:\\Users\\OM CHAVAN\\AppData\\Local\\Programs\\Python\\Python311\\Lib\\site-packages\\IPython\\core\\interactiveshell.py\", line 3448, in run_ast_nodes\n  File \"C:\\Users\\OM CHAVAN\\AppData\\Local\\Programs\\Python\\Python311\\Lib\\site-packages\\IPython\\core\\interactiveshell.py\", line 3508, in run_code\n  File \"C:\\Users\\OM CHAVAN\\AppData\\Local\\Temp\\ipykernel_62912\\2824488194.py\", line 12, in <module>\n  File \"C:\\Users\\OM CHAVAN\\AppData\\Local\\Programs\\Python\\Python311\\Lib\\site-packages\\tensorflow\\python\\training\\saver.py\", line 934, in __init__\n  File \"C:\\Users\\OM CHAVAN\\AppData\\Local\\Programs\\Python\\Python311\\Lib\\site-packages\\tensorflow\\python\\training\\saver.py\", line 946, in build\n  File \"C:\\Users\\OM CHAVAN\\AppData\\Local\\Programs\\Python\\Python311\\Lib\\site-packages\\tensorflow\\python\\training\\saver.py\", line 974, in _build\n  File \"C:\\Users\\OM CHAVAN\\AppData\\Local\\Programs\\Python\\Python311\\Lib\\site-packages\\tensorflow\\python\\training\\saver.py\", line 543, in _build_internal\n  File \"C:\\Users\\OM CHAVAN\\AppData\\Local\\Programs\\Python\\Python311\\Lib\\site-packages\\tensorflow\\python\\training\\saver.py\", line 360, in _AddRestoreOps\n  File \"C:\\Users\\OM CHAVAN\\AppData\\Local\\Programs\\Python\\Python311\\Lib\\site-packages\\tensorflow\\python\\training\\saver.py\", line 611, in bulk_restore\n  File \"C:\\Users\\OM CHAVAN\\AppData\\Local\\Programs\\Python\\Python311\\Lib\\site-packages\\tensorflow\\python\\ops\\gen_io_ops.py\", line 1610, in restore_v2\n  File \"C:\\Users\\OM CHAVAN\\AppData\\Local\\Programs\\Python\\Python311\\Lib\\site-packages\\tensorflow\\python\\framework\\op_def_library.py\", line 796, in _apply_op_helper\n  File \"C:\\Users\\OM CHAVAN\\AppData\\Local\\Programs\\Python\\Python311\\Lib\\site-packages\\tensorflow\\python\\framework\\ops.py\", line 2701, in _create_op_internal\n  File \"C:\\Users\\OM CHAVAN\\AppData\\Local\\Programs\\Python\\Python311\\Lib\\site-packages\\tensorflow\\python\\framework\\ops.py\", line 1196, in from_node_def\n"
     ]
    }
   ],
   "source": [
    "import tensorflow.compat.v1 as tf\n",
    "tf.disable_v2_behavior()\n",
    "\n",
    "# Rebuild the graph manually\n",
    "x = tf.placeholder(tf.float32, shape=[None, 10], name='x')\n",
    "y = tf.placeholder(tf.float32, shape=[None, 1], name='y')\n",
    "weights = tf.Variable(tf.random_normal([10, 1]), name='weights')\n",
    "bias = tf.Variable(tf.zeros([1]), name='bias')\n",
    "predictions = tf.add(tf.matmul(x, weights), bias, name='predictions')\n",
    "\n",
    "# Restore the model variables\n",
    "saver = tf.train.Saver()\n",
    "with tf.Session() as sess:\n",
    "    saver.restore(sess, 'saved_model/regression_model/model_22.keras')\n",
    "    print(\"Model restored successfully!\")\n"
   ]
  },
  {
   "cell_type": "code",
   "execution_count": 32,
   "id": "179766cc-971d-46ce-bf82-f25d099ccadd",
   "metadata": {},
   "outputs": [
    {
     "name": "stdout",
     "output_type": "stream",
     "text": [
      "Unable to open table file saved_model\\regression_model\\model_22.keras: DATA_LOSS: not an sstable (bad magic number): perhaps your file is in a different file format and you need to use a different restore operator?\n"
     ]
    }
   ],
   "source": [
    "from tensorflow.python.tools.inspect_checkpoint import print_tensors_in_checkpoint_file\n",
    "print_tensors_in_checkpoint_file(file_name='saved_model/regression_model/model_22.keras', tensor_name='', all_tensors=True)"
   ]
  },
  {
   "cell_type": "code",
   "execution_count": null,
   "id": "bc95ed99-baac-41c1-b2ef-993a9e397666",
   "metadata": {},
   "outputs": [],
   "source": []
  }
 ],
 "metadata": {
  "kernelspec": {
   "display_name": "Python 3 (ipykernel)",
   "language": "python",
   "name": "python3"
  },
  "language_info": {
   "codemirror_mode": {
    "name": "ipython",
    "version": 3
   },
   "file_extension": ".py",
   "mimetype": "text/x-python",
   "name": "python",
   "nbconvert_exporter": "python",
   "pygments_lexer": "ipython3",
   "version": "3.11.4"
  }
 },
 "nbformat": 4,
 "nbformat_minor": 5
}
